// ----------------------------------------------------------------------------------
// Copyright (c) The Standard Organization: A coalition of the Good-Hearted Engineers
// ----------------------------------------------------------------------------------

using System;
using System.Linq;
using System.Threading.Tasks;
using EFxceptions.Models.Exceptions;
using GitFyle.Core.Api.Models.Foundations.Sources;
using GitFyle.Core.Api.Models.Foundations.Sources.Exceptions;
using GitFyle.Core.Api.Tests.Unit.Services.Foundations.Sources;
using Microsoft.Data.SqlClient;
using Microsoft.EntityFrameworkCore;
using Xeptions;

namespace GitFyle.Core.Api.Services.Foundations.Sources
{
    internal partial class SourceService
    {
        private delegate ValueTask<Source> ReturningSourceFunction();
        private delegate ValueTask<IQueryable<Source>> ReturningSourcesFunction();

        private async ValueTask<Source> TryCatch(ReturningSourceFunction returningSourceFunction)
        {
            try
            {
                return await returningSourceFunction();
            }
            catch (NullSourceException nullSourceException)
            {
                throw await CreateAndLogValidationExceptionAsync(nullSourceException);
            }
            catch (InvalidSourceException invalidSourceException)
            {
                throw await CreateAndLogValidationExceptionAsync(invalidSourceException);
            }
            catch (NotFoundSourceException notFoundSourceException)
            {
                throw await CreateAndLogValidationExceptionAsync(notFoundSourceException);
            }
            catch (SqlException sqlException)
            {
                var failedStorageSourceException = new FailedStorageSourceException(
                    message: "Failed source storage error occurred, contact support.",
                    innerException: sqlException);

                throw await CreateAndLogCriticalDependencyExceptionAsync(failedStorageSourceException);
            }
            catch (DuplicateKeyException duplicateKeyException)
            {
                var alreadyExistsSourceException =
                    new AlreadyExistsSourceException(
                        message: "Source already exists error occurred.",
                        innerException: duplicateKeyException,
                        data: duplicateKeyException.Data);

                throw await CreateAndLogDependencyValidationExceptionAsync(alreadyExistsSourceException);
            }
            catch (DbUpdateConcurrencyException dbUpdateConcurrencyException)
            {
                var concurrencyGemException =
                    new LockedSourceException(
                        message: "Locked source record error occurred, please try again.",
                        innerException: dbUpdateConcurrencyException);

                throw await CreateAndLogDependencyValidationExceptionAsync(concurrencyGemException);
            }
            catch (DbUpdateException dbUpdateException)
            {
                var failedOperationSourceException =
                    new FailedOperationSourceException(
                        message: "Failed operation source  error occurred, contact support.",
                        innerException: dbUpdateException);

                throw await CreateAndLogDependencyExceptionAsync(failedOperationSourceException);
            }
            catch (Exception exception)
            {
                var failedServiceSourceException =
                    new FailedServiceSourceException(
                        message: "Failed service source error occurred, contact support.",
                        innerException: exception);

                throw await CreateAndLogServiceExceptionAsync(failedServiceSourceException);
            }
        }

        private async ValueTask<IQueryable<Source>> TryCatch(ReturningSourcesFunction returningSourcesFunction)
        {
            try
            {
                return await returningSourcesFunction();
            }
            catch (SqlException sqlException)
            {
                var failedStorageSourceException = new FailedStorageSourceException(
                    message: "Failed source storage error occurred, contact support.",
                    innerException: sqlException);

                throw await CreateAndLogCriticalDependencyExceptionAsync(failedStorageSourceException);
            }
            catch (Exception exception)
            {
                var failedServiceSourceException =
                    new FailedServiceSourceException(
                        message: "Failed service source error occurred, contact support.",
                        innerException: exception);

                throw await CreateAndLogServiceExceptionAsync(failedServiceSourceException);
            }
        }

        private async ValueTask<SourceValidationException> CreateAndLogValidationExceptionAsync(
            Xeption exception)
        {
            var sourceValidationException = new SourceValidationException(
                message: "Source validation error occurred, fix errors and try again.",
                innerException: exception);

            await this.loggingBroker.LogErrorAsync(sourceValidationException);

            return sourceValidationException;
        }

        private async ValueTask<SourceDependencyException> CreateAndLogCriticalDependencyExceptionAsync(
            Xeption exception)
        {
            var sourceDependencyException = new SourceDependencyException(
                message: "Source dependency error occurred, contact support.",
                innerException: exception);

            await this.loggingBroker.LogCriticalAsync(sourceDependencyException);

            return sourceDependencyException;
        }

        private async ValueTask<SourceDependencyValidationException> CreateAndLogDependencyValidationExceptionAsync(
            Xeption exception)
        {
            var sourceDependencyValidationException = new SourceDependencyValidationException(
                message: "Source dependency validation error occurred, fix errors and try again.",
                innerException: exception);

            await this.loggingBroker.LogErrorAsync(sourceDependencyValidationException);

            return sourceDependencyValidationException;
        }

        private async ValueTask<SourceDependencyException> CreateAndLogDependencyExceptionAsync(
            Xeption exception)
        {
            var sourceDependencyException = new SourceDependencyException(
                message: "Source dependency error occurred, contact support.",
                innerException: exception);

            await this.loggingBroker.LogErrorAsync(sourceDependencyException);

            return sourceDependencyException;
        }

        private async ValueTask<SourceServiceException> CreateAndLogServiceExceptionAsync(
           Xeption exception)
        {
            var sourceServiceException = new SourceServiceException(
                message: "Service error occurred, contact support.",
                innerException: exception);

            await this.loggingBroker.LogErrorAsync(sourceServiceException);

            return sourceServiceException;
        }
    }
}